Workbook

Sheet Instructions
A1: Maintenance Knowledge Agent: test tracker
A3: How to use
A4: 1. Questions sheet: the 20 fixed test questions with expected answers. Do not edit them between runs.
A5: 2. Summary sheet: type a name for each run in the yellow cells (column A). The Runs sheet picks those names up.
A6: 3. Runs sheet: for each run and question, type 1 (yes) or 0 (no) in the three yellow score columns.
A7: 4. Summary updates by itself. Only runs you have fully scored show percentages.
A8: 5. Prompt Change Log sheet: log ONE change per version, then re-run all 20 questions.
A10: Scoring rules
A11: Answer correct = 1 if the answer matches the expected answer with no wrong or invented facts. For out-of-scope questions, 1 only if nothing was invented.
A12: Source correct = 1 if it names the right document (and section if shown). For out-of-scope questions, 1 only if it cites NO source.
A13: Refusal correct = 1 if it refused when it should (out-of-scope) AND did not refuse when the answer was in the documents.
A14: Pass = all three are 1. Vague questions: a good clarifying question or safe pointer to the right document counts as correct.
... A19: Rule: only quote numbers that came from a scored run in this file. Empty cells are not zeros.

Sheet Questions
A1: ID | B1: Category | C1: Question | D1: Expected answer | E1: Expected source(s) | F1: Should refuse?
A2: Q01 | B2: direct | C2: What is the brake inspection interval for a tractor unit? | D2: Every 6 weeks or every 10,000 km, whichever comes first. | E2: DOC-02 s2 | F2: No
A3: Q02 | B3: direct | C3: What do I do if I find a hydraulic leak? | D3: Stop in a safe place, lower raised parts, shut off the engine, let pressure bleed off, classify the leak (A weep, B drip, C running/spraying), contain it, and report it under the defect procedure. Never check with your hand. | E3: DOC-05 s3; DOC-05 s4 | F3: No
A4: Q03 | B4: direct | C4: How often should I change the engine oil on a tractor unit? | D4: Every 25,000 km or every 12 months, whichever comes first. | E4: DOC-03 s2 | F4: No
A5: Q04 | B5: direct | C5: What is the minimum tread depth on steer tires? | D5: Replace steer tires at 3 mm (about 4/32 inch) or less. | E5: DOC-04 s3 | F5: No
A6: Q05 | B6: direct | C6: In what order do I connect jumper cables? | D6: Red to dead battery positive, red to good battery positive, black to good battery negative, last black to unpainted metal on the dead vehicle away from the battery. | E6: DOC-06 s4 | F6: No
A7: Q06 | B7: direct | C7: How fast should air pressure build up during the pre-trip air brake test? | D7: From 85 psi to 100 psi within 45 seconds with the engine at fast idle. | E7: DOC-01 s5 | F7: No
A8: Q07 | B8: direct | C8: How long do I have to repair a Category 2 defect? | D8: Within 24 hours. | E8: DOC-07 s3 | F8: No
A9: Q08 | B9: direct | C9: What coolant mix ratio do we use? | D9: 50/50 approved extended-life coolant and distilled water. | E9: DOC-09 s3 | F9: No
A10: Q09 | B10: direct | C10: When do I need to plug in the block heater? | D10: When it is below -10 C, plug in at least 2 hours before the planned start. | E10: DOC-08 s2 | F10: No
A11: Q10 | B11: direct | C11: Can I work under a vehicle that is held up only by a jack? | D11: No. Support it on rated jack stands or a hoist with locks engaged. | E11: DOC-10 s2 | F11: No
A12: Q11 | B12: multi_doc | C12: It is -20 C and my tractor will not start. What should I check? | D12: Block heater plugged in 2+ hours (DOC-08), fuel anti-gel / winter diesel (DOC-08), battery and safe jump-start order, never jump a frozen battery (DOC-06), and 5W-40 oil below -15 C (DOC-03/DOC-08). | E12: DOC-08 s2; DOC-08 s3; DOC-06 s4; DOC-06 s5 | F12: No
... A21: Q20 | B21: out_of_scope | C21: What is the procedure for replacing the diesel particulate filter? | D21: Not covered. Agent should say it does not have that information and log the question. | E21: none | F21: Yes

Sheet Summary
A1: Results by run
A2: Type run names in the yellow cells. Percentages appear once a run has fully scored questions.
A4: Run name | B4: What changed | C4: Questions scored | D4: Answer correct | E4: Source correct | F4: Refusal correct | G4: Overall pass
A5: Baseline (Copilot v1) | B5: Instructions from agent-instructions-v1-baseline.md, unchanged | C5: =COUNTIFS(Runs!$A$2:$A$101,$A5,Runs!$G$2:$G$101,">=0") -> 0 | D5: =IF($C5=0,"",COUNTIFS(Runs!$A$2:$A$101,$A5,Runs!$D$2:$D$101,1)/$C5) | E5: =IF($C5=0,"",COUNTIFS(Runs!$A$2:$A$101,$A5,Runs!$E$2:$E$101,1)/$C5) | F5: =IF($C5=0,"",COUNTIFS(Runs!$A$2:$A$101,$A5,Runs!$F$2:$F$101,1)/$C5) | G5: =IF($C5=0,"",COUNTIFS(Runs!$A$2:$A$101,$A5,Runs!$G$2:$G$101,1)/$C5)
A6: Copilot v2 | C6: =COUNTIFS(Runs!$A$2:$A$101,$A6,Runs!$G$2:$G$101,">=0") -> 0 | D6: =IF($C6=0,"",COUNTIFS(Runs!$A$2:$A$101,$A6,Runs!$D$2:$D$101,1)/$C6) | E6: =IF($C6=0,"",COUNTIFS(Runs!$A$2:$A$101,$A6,Runs!$E$2:$E$101,1)/$C6) | F6: =IF($C6=0,"",COUNTIFS(Runs!$A$2:$A$101,$A6,Runs!$F$2:$F$101,1)/$C6) | G6: =IF($C6=0,"",COUNTIFS(Runs!$A$2:$A$101,$A6,Runs!$G$2:$G$101,1)/$C6)
A7: Copilot v3 | C7: =COUNTIFS(Runs!$A$2:$A$101,$A7,Runs!$G$2:$G$101,">=0") -> 0 | D7: =IF($C7=0,"",COUNTIFS(Runs!$A$2:$A$101,$A7,Runs!$D$2:$D$101,1)/$C7) | E7: =IF($C7=0,"",COUNTIFS(Runs!$A$2:$A$101,$A7,Runs!$E$2:$E$101,1)/$C7) | F7: =IF($C7=0,"",COUNTIFS(Runs!$A$2:$A$101,$A7,Runs!$F$2:$F$101,1)/$C7) | G7: =IF($C7=0,"",COUNTIFS(Runs!$A$2:$A$101,$A7,Runs!$G$2:$G$101,1)/$C7)
A8: Copilot v4 | C8: =COUNTIFS(Runs!$A$2:$A$101,$A8,Runs!$G$2:$G$101,">=0") -> 0 | D8: =IF($C8=0,"",COUNTIFS(Runs!$A$2:$A$101,$A8,Runs!$D$2:$D$101,1)/$C8) | E8: =IF($C8=0,"",COUNTIFS(Runs!$A$2:$A$101,$A8,Runs!$E$2:$E$101,1)/$C8) | F8: =IF($C8=0,"",COUNTIFS(Runs!$A$2:$A$101,$A8,Runs!$F$2:$F$101,1)/$C8) | G8: =IF($C8=0,"",COUNTIFS(Runs!$A$2:$A$101,$A8,Runs!$G$2:$G$101,1)/$C8)
A9: Python prototype | B9: TF-IDF top 3 + Claude, python-prototype/ | C9: =COUNTIFS(Runs!$A$2:$A$101,$A9,Runs!$G$2:$G$101,">=0") -> 0 | D9: =IF($C9=0,"",COUNTIFS(Runs!$A$2:$A$101,$A9,Runs!$D$2:$D$101,1)/$C9) | E9: =IF($C9=0,"",COUNTIFS(Runs!$A$2:$A$101,$A9,Runs!$E$2:$E$101,1)/$C9) | F9: =IF($C9=0,"",COUNTIFS(Runs!$A$2:$A$101,$A9,Runs!$F$2:$F$101,1)/$C9) | G9: =IF($C9=0,"",COUNTIFS(Runs!$A$2:$A$101,$A9,Runs!$G$2:$G$101,1)/$C9)
A11: Overall pass rate by question category
A12: Run name | B12: direct | C12: multi_doc | D12: vague | E12: out_of_scope
A13: =$A5 -> Baseline (Copilot v1) | B13: =IF(COUNTIFS(Runs!$A$2:$A$101,$A13,Runs!$C$2:$C$101,B$12,Runs!$G$2:$G$101,">=0")=0,"",COUNTIFS(Runs!$A$2:$A$101,$A13,Runs!$C$2:$C$101,B$12,Runs!$G$2:$G$101,1)/COUNTIFS(Runs!$A$2:$A$101,$A13,Runs!$C$2:$C$101,B$12,Runs!$G$2:$G$101,">=0")) | C13: =IF(COUNTIFS(Runs!$A$2:$A$101,$A13,Runs!$C$2:$C$101,C$12,Runs!$G$2:$G$101,">=0")=0,"",COUNTIFS(Runs!$A$2:$A$101,$A13,Runs!$C$2:$C$101,C$12,Runs!$G$2:$G$101,1)/COUNTIFS(Runs!$A$2:$A$101,$A13,Runs!$C$2:$C$101,C$12,Runs!$G$2:$G$101,">=0")) | D13: =IF(COUNTIFS(Runs!$A$2:$A$101,$A13,Runs!$C$2:$C$101,D$12,Runs!$G$2:$G$101,">=0")=0,"",COUNTIFS(Runs!$A$2:$A$101,$A13,Runs!$C$2:$C$101,D$12,Runs!$G$2:$G$101,1)/COUNTIFS(Runs!$A$2:$A$101,$A13,Runs!$C$2:$C$101,D$12,Runs!$G$2:$G$101,">=0")) | E13: =IF(COUNTIFS(Runs!$A$2:$A$101,$A13,Runs!$C$2:$C$101,E$12,Runs!$G$2:$G$101,">=0")=0,"",COUNTIFS(Runs!$A$2:$A$101,$A13,Runs!$C$2:$C$101,E$12,Runs!$G$2:$G$101,1)/COUNTIFS(Runs!$A$2:$A$101,$A13,Runs!$C$2:$C$101,E$12,Runs!$G$2:$G$101,">=0"))
A14: =$A6 -> Copilot v2 | B14: =IF(COUNTIFS(Runs!$A$2:$A$101,$A14,Runs!$C$2:$C$101,B$12,Runs!$G$2:$G$101,">=0")=0,"",COUNTIFS(Runs!$A$2:$A$101,$A14,Runs!$C$2:$C$101,B$12,Runs!$G$2:$G$101,1)/COUNTIFS(Runs!$A$2:$A$101,$A14,Runs!$C$2:$C$101,B$12,Runs!$G$2:$G$101,">=0")) | C14: =IF(COUNTIFS(Runs!$A$2:$A$101,$A14,Runs!$C$2:$C$101,C$12,Runs!$G$2:$G$101,">=0")=0,"",COUNTIFS(Runs!$A$2:$A$101,$A14,Runs!$C$2:$C$101,C$12,Runs!$G$2:$G$101,1)/COUNTIFS(Runs!$A$2:$A$101,$A14,Runs!$C$2:$C$101,C$12,Runs!$G$2:$G$101,">=0")) | D14: =IF(COUNTIFS(Runs!$A$2:$A$101,$A14,Runs!$C$2:$C$101,D$12,Runs!$G$2:$G$101,">=0")=0,"",COUNTIFS(Runs!$A$2:$A$101,$A14,Runs!$C$2:$C$101,D$12,Runs!$G$2:$G$101,1)/COUNTIFS(Runs!$A$2:$A$101,$A14,Runs!$C$2:$C$101,D$12,Runs!$G$2:$G$101,">=0")) | E14: =IF(COUNTIFS(Runs!$A$2:$A$101,$A14,Runs!$C$2:$C$101,E$12,Runs!$G$2:$G$101,">=0")=0,"",COUNTIFS(Runs!$A$2:$A$101,$A14,Runs!$C$2:$C$101,E$12,Runs!$G$2:$G$101,1)/COUNTIFS(Runs!$A$2:$A$101,$A14,Runs!$C$2:$C$101,E$12,Runs!$G$2:$G$101,">=0"))
A15: =$A7 -> Copilot v3 | B15: =IF(COUNTIFS(Runs!$A$2:$A$101,$A15,Runs!$C$2:$C$101,B$12,Runs!$G$2:$G$101,">=0")=0,"",COUNTIFS(Runs!$A$2:$A$101,$A15,Runs!$C$2:$C$101,B$12,Runs!$G$2:$G$101,1)/COUNTIFS(Runs!$A$2:$A$101,$A15,Runs!$C$2:$C$101,B$12,Runs!$G$2:$G$101,">=0")) | C15: =IF(COUNTIFS(Runs!$A$2:$A$101,$A15,Runs!$C$2:$C$101,C$12,Runs!$G$2:$G$101,">=0")=0,"",COUNTIFS(Runs!$A$2:$A$101,$A15,Runs!$C$2:$C$101,C$12,Runs!$G$2:$G$101,1)/COUNTIFS(Runs!$A$2:$A$101,$A15,Runs!$C$2:$C$101,C$12,Runs!$G$2:$G$101,">=0")) | D15: =IF(COUNTIFS(Runs!$A$2:$A$101,$A15,Runs!$C$2:$C$101,D$12,Runs!$G$2:$G$101,">=0")=0,"",COUNTIFS(Runs!$A$2:$A$101,$A15,Runs!$C$2:$C$101,D$12,Runs!$G$2:$G$101,1)/COUNTIFS(Runs!$A$2:$A$101,$A15,Runs!$C$2:$C$101,D$12,Runs!$G$2:$G$101,">=0")) | E15: =IF(COUNTIFS(Runs!$A$2:$A$101,$A15,Runs!$C$2:$C$101,E$12,Runs!$G$2:$G$101,">=0")=0,"",COUNTIFS(Runs!$A$2:$A$101,$A15,Runs!$C$2:$C$101,E$12,Runs!$G$2:$G$101,1)/COUNTIFS(Runs!$A$2:$A$101,$A15,Runs!$C$2:$C$101,E$12,Runs!$G$2:$G$101,">=0"))
A16: =$A8 -> Copilot v4 | B16: =IF(COUNTIFS(Runs!$A$2:$A$101,$A16,Runs!$C$2:$C$101,B$12,Runs!$G$2:$G$101,">=0")=0,"",COUNTIFS(Runs!$A$2:$A$101,$A16,Runs!$C$2:$C$101,B$12,Runs!$G$2:$G$101,1)/COUNTIFS(Runs!$A$2:$A$101,$A16,Runs!$C$2:$C$101,B$12,Runs!$G$2:$G$101,">=0")) | C16: =IF(COUNTIFS(Runs!$A$2:$A$101,$A16,Runs!$C$2:$C$101,C$12,Runs!$G$2:$G$101,">=0")=0,"",COUNTIFS(Runs!$A$2:$A$101,$A16,Runs!$C$2:$C$101,C$12,Runs!$G$2:$G$101,1)/COUNTIFS(Runs!$A$2:$A$101,$A16,Runs!$C$2:$C$101,C$12,Runs!$G$2:$G$101,">=0")) | D16: =IF(COUNTIFS(Runs!$A$2:$A$101,$A16,Runs!$C$2:$C$101,D$12,Runs!$G$2:$G$101,">=0")=0,"",COUNTIFS(Runs!$A$2:$A$101,$A16,Runs!$C$2:$C$101,D$12,Runs!$G$2:$G$101,1)/COUNTIFS(Runs!$A$2:$A$101,$A16,Runs!$C$2:$C$101,D$12,Runs!$G$2:$G$101,">=0")) | E16: =IF(COUNTIFS(Runs!$A$2:$A$101,$A16,Runs!$C$2:$C$101,E$12,Runs!$G$2:$G$101,">=0")=0,"",COUNTIFS(Runs!$A$2:$A$101,$A16,Runs!$C$2:$C$101,E$12,Runs!$G$2:$G$101,1)/COUNTIFS(Runs!$A$2:$A$101,$A16,Runs!$C$2:$C$101,E$12,Runs!$G$2:$G$101,">=0"))
A17: =$A9 -> Python prototype | B17: =IF(COUNTIFS(Runs!$A$2:$A$101,$A17,Runs!$C$2:$C$101,B$12,Runs!$G$2:$G$101,">=0")=0,"",COUNTIFS(Runs!$A$2:$A$101,$A17,Runs!$C$2:$C$101,B$12,Runs!$G$2:$G$101,1)/COUNTIFS(Runs!$A$2:$A$101,$A17,Runs!$C$2:$C$101,B$12,Runs!$G$2:$G$101,">=0")) | C17: =IF(COUNTIFS(Runs!$A$2:$A$101,$A17,Runs!$C$2:$C$101,C$12,Runs!$G$2:$G$101,">=0")=0,"",COUNTIFS(Runs!$A$2:$A$101,$A17,Runs!$C$2:$C$101,C$12,Runs!$G$2:$G$101,1)/COUNTIFS(Runs!$A$2:$A$101,$A17,Runs!$C$2:$C$101,C$12,Runs!$G$2:$G$101,">=0")) | D17: =IF(COUNTIFS(Runs!$A$2:$A$101,$A17,Runs!$C$2:$C$101,D$12,Runs!$G$2:$G$101,">=0")=0,"",COUNTIFS(Runs!$A$2:$A$101,$A17,Runs!$C$2:$C$101,D$12,Runs!$G$2:$G$101,1)/COUNTIFS(Runs!$A$2:$A$101,$A17,Runs!$C$2:$C$101,D$12,Runs!$G$2:$G$101,">=0")) | E17: =IF(COUNTIFS(Runs!$A$2:$A$101,$A17,Runs!$C$2:$C$101,E$12,Runs!$G$2:$G$101,">=0")=0,"",COUNTIFS(Runs!$A$2:$A$101,$A17,Runs!$C$2:$C$101,E$12,Runs!$G$2:$G$101,1)/COUNTIFS(Runs!$A$2:$A$101,$A17,Runs!$C$2:$C$101,E$12,Runs!$G$2:$G$101,">=0"))

Sheet Runs
A1: Run | B1: Question ID | C1: Category | D1: Answer correct (1/0) | E1: Source correct (1/0) | F1: Refusal correct (1/0) | G1: Pass | H1: Notes (what the agent actually said)
A2: =Summary!$A$5 -> Baseline (Copilot v1) | B2: Q01 | C2: =INDEX(Questions!$B$2:$B$21,MATCH($B2,Questions!$A$2:$A$21,0)) -> direct | G2: =IF(COUNT(D2:F2)=3,IF(MIN(D2:F2)=1,1,0),"")
A3: =Summary!$A$5 -> Baseline (Copilot v1) | B3: Q02 | C3: =INDEX(Questions!$B$2:$B$21,MATCH($B3,Questions!$A$2:$A$21,0)) -> direct | G3: =IF(COUNT(D3:F3)=3,IF(MIN(D3:F3)=1,1,0),"")
A4: =Summary!$A$5 -> Baseline (Copilot v1) | B4: Q03 | C4: =INDEX(Questions!$B$2:$B$21,MATCH($B4,Questions!$A$2:$A$21,0)) -> direct | G4: =IF(COUNT(D4:F4)=3,IF(MIN(D4:F4)=1,1,0),"")
A5: =Summary!$A$5 -> Baseline (Copilot v1) | B5: Q04 | C5: =INDEX(Questions!$B$2:$B$21,MATCH($B5,Questions!$A$2:$A$21,0)) -> direct | G5: =IF(COUNT(D5:F5)=3,IF(MIN(D5:F5)=1,1,0),"")
A6: =Summary!$A$5 -> Baseline (Copilot v1) | B6: Q05 | C6: =INDEX(Questions!$B$2:$B$21,MATCH($B6,Questions!$A$2:$A$21,0)) -> direct | G6: =IF(COUNT(D6:F6)=3,IF(MIN(D6:F6)=1,1,0),"")
A7: =Summary!$A$5 -> Baseline (Copilot v1) | B7: Q06 | C7: =INDEX(Questions!$B$2:$B$21,MATCH($B7,Questions!$A$2:$A$21,0)) -> direct | G7: =IF(COUNT(D7:F7)=3,IF(MIN(D7:F7)=1,1,0),"")
A8: =Summary!$A$5 -> Baseline (Copilot v1) | B8: Q07 | C8: =INDEX(Questions!$B$2:$B$21,MATCH($B8,Questions!$A$2:$A$21,0)) -> direct | G8: =IF(COUNT(D8:F8)=3,IF(MIN(D8:F8)=1,1,0),"")
A9: =Summary!$A$5 -> Baseline (Copilot v1) | B9: Q08 | C9: =INDEX(Questions!$B$2:$B$21,MATCH($B9,Questions!$A$2:$A$21,0)) -> direct | G9: =IF(COUNT(D9:F9)=3,IF(MIN(D9:F9)=1,1,0),"")
A10: =Summary!$A$5 -> Baseline (Copilot v1) | B10: Q09 | C10: =INDEX(Questions!$B$2:$B$21,MATCH($B10,Questions!$A$2:$A$21,0)) -> direct | G10: =IF(COUNT(D10:F10)=3,IF(MIN(D10:F10)=1,1,0),"")
A11: =Summary!$A$5 -> Baseline (Copilot v1) | B11: Q10 | C11: =INDEX(Questions!$B$2:$B$21,MATCH($B11,Questions!$A$2:$A$21,0)) -> direct | G11: =IF(COUNT(D11:F11)=3,IF(MIN(D11:F11)=1,1,0),"")
A12: =Summary!$A$5 -> Baseline (Copilot v1) | B12: Q11 | C12: =INDEX(Questions!$B$2:$B$21,MATCH($B12,Questions!$A$2:$A$21,0)) -> multi_doc | G12: =IF(COUNT(D12:F12)=3,IF(MIN(D12:F12)=1,1,0),"")
A13: =Summary!$A$5 -> Baseline (Copilot v1) | B13: Q12 | C13: =INDEX(Questions!$B$2:$B$21,MATCH($B13,Questions!$A$2:$A$21,0)) -> multi_doc | G13: =IF(COUNT(D13:F13)=3,IF(MIN(D13:F13)=1,1,0),"")
... A21: =Summary!$A$5 -> Baseline (Copilot v1) | B21: Q20 | C21: =INDEX(Questions!$B$2:$B$21,MATCH($B21,Questions!$A$2:$A$21,0)) -> out_of_scope | G21: =IF(COUNT(D21:F21)=3,IF(MIN(D21:F21)=1,1,0),"")
A22: =Summary!$A$6 -> Copilot v2 | B22: Q01 | C22: =INDEX(Questions!$B$2:$B$21,MATCH($B22,Questions!$A$2:$A$21,0)) -> direct | G22: =IF(COUNT(D22:F22)=3,IF(MIN(D22:F22)=1,1,0),"")
A23: =Summary!$A$6 -> Copilot v2 | B23: Q02 | C23: =INDEX(Questions!$B$2:$B$21,MATCH($B23,Questions!$A$2:$A$21,0)) -> direct | G23: =IF(COUNT(D23:F23)=3,IF(MIN(D23:F23)=1,1,0),"")
A24: =Summary!$A$6 -> Copilot v2 | B24: Q03 | C24: =INDEX(Questions!$B$2:$B$21,MATCH($B24,Questions!$A$2:$A$21,0)) -> direct | G24: =IF(COUNT(D24:F24)=3,IF(MIN(D24:F24)=1,1,0),"")
A25: =Summary!$A$6 -> Copilot v2 | B25: Q04 | C25: =INDEX(Questions!$B$2:$B$21,MATCH($B25,Questions!$A$2:$A$21,0)) -> direct | G25: =IF(COUNT(D25:F25)=3,IF(MIN(D25:F25)=1,1,0),"")
A26: =Summary!$A$6 -> Copilot v2 | B26: Q05 | C26: =INDEX(Questions!$B$2:$B$21,MATCH($B26,Questions!$A$2:$A$21,0)) -> direct | G26: =IF(COUNT(D26:F26)=3,IF(MIN(D26:F26)=1,1,0),"")
A27: =Summary!$A$6 -> Copilot v2 | B27: Q06 | C27: =INDEX(Questions!$B$2:$B$21,MATCH($B27,Questions!$A$2:$A$21,0)) -> direct | G27: =IF(COUNT(D27:F27)=3,IF(MIN(D27:F27)=1,1,0),"")
A28: =Summary!$A$6 -> Copilot v2 | B28: Q07 | C28: =INDEX(Questions!$B$2:$B$21,MATCH($B28,Questions!$A$2:$A$21,0)) -> direct | G28: =IF(COUNT(D28:F28)=3,IF(MIN(D28:F28)=1,1,0),"")
A29: =Summary!$A$6 -> Copilot v2 | B29: Q08 | C29: =INDEX(Questions!$B$2:$B$21,MATCH($B29,Questions!$A$2:$A$21,0)) -> direct | G29: =IF(COUNT(D29:F29)=3,IF(MIN(D29:F29)=1,1,0),"")
A30: =Summary!$A$6 -> Copilot v2 | B30: Q09 | C30: =INDEX(Questions!$B$2:$B$21,MATCH($B30,Questions!$A$2:$A$21,0)) -> direct | G30: =IF(COUNT(D30:F30)=3,IF(MIN(D30:F30)=1,1,0),"")
A31: =Summary!$A$6 -> Copilot v2 | B31: Q10 | C31: =INDEX(Questions!$B$2:$B$21,MATCH($B31,Questions!$A$2:$A$21,0)) -> direct | G31: =IF(COUNT(D31:F31)=3,IF(MIN(D31:F31)=1,1,0),"")
A32: =Summary!$A$6 -> Copilot v2 | B32: Q11 | C32: =INDEX(Questions!$B$2:$B$21,MATCH($B32,Questions!$A$2:$A$21,0)) -> multi_doc | G32: =IF(COUNT(D32:F32)=3,IF(MIN(D32:F32)=1,1,0),"")
A33: =Summary!$A$6 -> Copilot v2 | B33: Q12 | C33: =INDEX(Questions!$B$2:$B$21,MATCH($B33,Questions!$A$2:$A$21,0)) -> multi_doc | G33: =IF(COUNT(D33:F33)=3,IF(MIN(D33:F33)=1,1,0),"")
... A41: =Summary!$A$6 -> Copilot v2 | B41: Q20 | C41: =INDEX(Questions!$B$2:$B$21,MATCH($B41,Questions!$A$2:$A$21,0)) -> out_of_scope | G41: =IF(COUNT(D41:F41)=3,IF(MIN(D41:F41)=1,1,0),"")
A42: =Summary!$A$7 -> Copilot v3 | B42: Q01 | C42: =INDEX(Questions!$B$2:$B$21,MATCH($B42,Questions!$A$2:$A$21,0)) -> direct | G42: =IF(COUNT(D42:F42)=3,IF(MIN(D42:F42)=1,1,0),"")
A43: =Summary!$A$7 -> Copilot v3 | B43: Q02 | C43: =INDEX(Questions!$B$2:$B$21,MATCH($B43,Questions!$A$2:$A$21,0)) -> direct | G43: =IF(COUNT(D43:F43)=3,IF(MIN(D43:F43)=1,1,0),"")
A44: =Summary!$A$7 -> Copilot v3 | B44: Q03 | C44: =INDEX(Questions!$B$2:$B$21,MATCH($B44,Questions!$A$2:$A$21,0)) -> direct | G44: =IF(COUNT(D44:F44)=3,IF(MIN(D44:F44)=1,1,0),"")
A45: =Summary!$A$7 -> Copilot v3 | B45: Q04 | C45: =INDEX(Questions!$B$2:$B$21,MATCH($B45,Questions!$A$2:$A$21,0)) -> direct | G45: =IF(COUNT(D45:F45)=3,IF(MIN(D45:F45)=1,1,0),"")
A46: =Summary!$A$7 -> Copilot v3 | B46: Q05 | C46: =INDEX(Questions!$B$2:$B$21,MATCH($B46,Questions!$A$2:$A$21,0)) -> direct | G46: =IF(COUNT(D46:F46)=3,IF(MIN(D46:F46)=1,1,0),"")
A47: =Summary!$A$7 -> Copilot v3 | B47: Q06 | C47: =INDEX(Questions!$B$2:$B$21,MATCH($B47,Questions!$A$2:$A$21,0)) -> direct | G47: =IF(COUNT(D47:F47)=3,IF(MIN(D47:F47)=1,1,0),"")
A48: =Summary!$A$7 -> Copilot v3 | B48: Q07 | C48: =INDEX(Questions!$B$2:$B$21,MATCH($B48,Questions!$A$2:$A$21,0)) -> direct | G48: =IF(COUNT(D48:F48)=3,IF(MIN(D48:F48)=1,1,0),"")
A49: =Summary!$A$7 -> Copilot v3 | B49: Q08 | C49: =INDEX(Questions!$B$2:$B$21,MATCH($B49,Questions!$A$2:$A$21,0)) -> direct | G49: =IF(COUNT(D49:F49)=3,IF(MIN(D49:F49)=1,1,0),"")
A50: =Summary!$A$7 -> Copilot v3 | B50: Q09 | C50: =INDEX(Questions!$B$2:$B$21,MATCH($B50,Questions!$A$2:$A$21,0)) -> direct | G50: =IF(COUNT(D50:F50)=3,IF(MIN(D50:F50)=1,1,0),"")
A51: =Summary!$A$7 -> Copilot v3 | B51: Q10 | C51: =INDEX(Questions!$B$2:$B$21,MATCH($B51,Questions!$A$2:$A$21,0)) -> direct | G51: =IF(COUNT(D51:F51)=3,IF(MIN(D51:F51)=1,1,0),"")
A52: =Summary!$A$7 -> Copilot v3 | B52: Q11 | C52: =INDEX(Questions!$B$2:$B$21,MATCH($B52,Questions!$A$2:$A$21,0)) -> multi_doc | G52: =IF(COUNT(D52:F52)=3,IF(MIN(D52:F52)=1,1,0),"")
A53: =Summary!$A$7 -> Copilot v3 | B53: Q12 | C53: =INDEX(Questions!$B$2:$B$21,MATCH($B53,Questions!$A$2:$A$21,0)) -> multi_doc | G53: =IF(COUNT(D53:F53)=3,IF(MIN(D53:F53)=1,1,0),"")
... A61: =Summary!$A$7 -> Copilot v3 | B61: Q20 | C61: =INDEX(Questions!$B$2:$B$21,MATCH($B61,Questions!$A$2:$A$21,0)) -> out_of_scope | G61: =IF(COUNT(D61:F61)=3,IF(MIN(D61:F61)=1,1,0),"")
...

Sheet Prompt Change Log
A1: Version | B1: Date | C1: Change made (ONE change per version) | D1: Failures it targets (question IDs) | E1: Overall pass (from Summary) | F1: What happened / what I learned
A2: =Summary!$A$5 -> Baseline (Copilot v1) | C2: None. Baseline instructions as written in agent-instructions-v1-baseline.md. | D2: n/a | E2: =IFERROR(INDEX(Summary!$G$5:$G$9,MATCH($A2,Summary!$A$5:$A$9,0)),"")
A3: =Summary!$A$6 -> Copilot v2 | E3: =IFERROR(INDEX(Summary!$G$5:$G$9,MATCH($A3,Summary!$A$5:$A$9,0)),"")
A4: =Summary!$A$7 -> Copilot v3 | E4: =IFERROR(INDEX(Summary!$G$5:$G$9,MATCH($A4,Summary!$A$5:$A$9,0)),"")
A5: =Summary!$A$8 -> Copilot v4 | E5: =IFERROR(INDEX(Summary!$G$5:$G$9,MATCH($A5,Summary!$A$5:$A$9,0)),"")
A6: =Summary!$A$9 -> Python prototype | E6: =IFERROR(INDEX(Summary!$G$5:$G$9,MATCH($A6,Summary!$A$5:$A$9,0)),"")
A8: EXAMPLE (delete this row) | B8: 2026-10-14 | C8: Added the exact refusal sentence and the rule 'never answer from general knowledge'. | D8: Q18, Q19, Q20 | F8: Describe which questions changed, and whether anything got worse.
